2025-07-12 19:35:27,940 - ERROR - Error during admin login: Traceback (most recent call last):
  File "E:\workspace\poc\vehicle_management_system\app\routers\authentication.py", line 74, in user_login
    logging.info(f"Login attempt for {login_details.email}")
  File "E:\workspace\poc\vehicle_management_system\myenv\lib\site-packages\pydantic\main.py", line 991, in __getattr__
    raise AttributeError(f'{type(self).__name__!r} object has no attribute {item!r}')
AttributeError: 'LoginRequest' object has no attribute 'email'

2025-07-12 19:36:04,337 - INFO - Login attempt for admin123
2025-07-12 19:36:05,571 - ERROR - Error during admin login: Traceback (most recent call last):
  File "E:\workspace\poc\vehicle_management_system\app\routers\authentication.py", line 84, in user_login
    if login_details.passwordHash != user_data["passwordHash"]:
KeyError: 'passwordHash'

2025-07-12 19:36:46,500 - INFO - Login attempt for admin123
